#!/usr/bin/env python@PY_VERSION@
#
# SPDX-License-Identifier: LGPL-2.1-or-later
#
# Copyright (C) 2017-2023 Red Hat, Inc.
#
# Author: Tony Asleson <tasleson@redhat.com>
#         Gris Ge <fge@redhat.com>

import sys
import syslog
import traceback

try:
    from lsm import PluginRunner
    from local_plugin import LocalPlugin

    if __name__ == '__main__':
        PluginRunner(LocalPlugin, sys.argv).run()
except Exception:
    # This should be quite rare, but when it does happen this is pretty
    # key in understanding what happened, especially when it happens when
    # running from the daemon.
    msg = str(traceback.format_exc())
    syslog.syslog(syslog.LOG_ERR, msg)
    sys.stderr.write(msg)
    sys.exit(1)
